<testsuite name="tools.plenary-to-junit.testdata.error_in_describe_with_failure_spec" tests="3" failures="1" skipped="0" errors="1">
  <testcase name="describe 2 passes"></testcase>
  <testcase name="describe 2 fails">
    <failure message="...o-junit/testdata/error_in_describe_with_failure_spec.lua:9: error message"><![CDATA[stack traceback:
	...o-junit/testdata/error_in_describe_with_failure_spec.lua:9: in function <...o-junit/testdata/error_in_describe_with_failure_spec.lua:8>]]></failure>
  </testcase>
  <testcase name="error_in_describe_with_failure_spec">
    <error message="Unexpected error reported. This usually occurs when an error is raised outside of an &#34;it&#34; block."><![CDATA[{ {
    descriptions = { "describe 1 has error" },
    msg = "...o-junit/testdata/error_in_describe_with_failure_spec.lua:2: error message\n\nstack traceback:\n\t...o-junit/testdata/error_in_describe_with_failure_spec.lua:2: in function <...o-junit/testdata/error_in_describe_with_failure_spec.lua:1>\n"
  } }	{
  errs = { {
      descriptions = { "describe 1 has error" },
      msg = "...o-junit/testdata/error_in_describe_with_failure_spec.lua:2: error message\n\nstack traceback:\n\t...o-junit/testdata/error_in_describe_with_failure_spec.lua:2: in function <...o-junit/testdata/error_in_describe_with_failure_spec.lua:1>\n"
    } },
  fail = { {
      descriptions = { "describe 2", "fails" },
      msg = "...o-junit/testdata/error_in_describe_with_failure_spec.lua:9: error message\n\nstack traceback:\n\t...o-junit/testdata/error_in_describe_with_failure_spec.lua:9: in function <...o-junit/testdata/error_in_describe_with_failure_spec.lua:8>\n"
    } },
  pass = { {
      descriptions = { "describe 2", "passes" }
    } }
}	]]></error>
  </testcase>
</testsuite>
