<testsuite name="tools.plenary-to-junit.testdata.error_in_describe_spec" tests="2" failures="0" skipped="0" errors="1">
  <testcase name="describe 2 passes"></testcase>
  <testcase name="error_in_describe_spec">
    <error message="Unexpected error reported. This usually occurs when an error is raised outside of an &#34;it&#34; block."><![CDATA[{ {
    descriptions = { "describe 1 has error" },
    msg = "tools/plenary-to-junit/testdata/error_in_describe_spec.lua:2: error message\n\nstack traceback:\n\ttools/plenary-to-junit/testdata/error_in_describe_spec.lua:2: in function <tools/plenary-to-junit/testdata/error_in_describe_spec.lua:1>\n"
  } }	{
  errs = { {
      descriptions = { "describe 1 has error" },
      msg = "tools/plenary-to-junit/testdata/error_in_describe_spec.lua:2: error message\n\nstack traceback:\n\ttools/plenary-to-junit/testdata/error_in_describe_spec.lua:2: in function <tools/plenary-to-junit/testdata/error_in_describe_spec.lua:1>\n"
    } },
  fail = {},
  pass = { {
      descriptions = { "describe 2", "passes" }
    } }
}	]]></error>
  </testcase>
</testsuite>
